Workbook

Sheet Financial Dashboard
A1: Startup
A2: Minor Financial Projections for a pitch deck
B4: Legend
B5: Provided by client
B6: Assumed | D6: Note: Can be changed
B7: Calculated | D7: Note: Should not be changed
M30: 9.1
M31: Total Increase in Revenue

Sheet Monthly BrakeDown
B1: Financials
B2: Income statement projection
A4: Revenue * | B4: Assumtion data | C4: 1st Month | D4: 2nd | E4: 3rd | F4: 4th | G4: 5th | H4: 6th | I4: Next Phase | J4: 7th | K4: 8th | L4: 9th | M4: 10th | N4: 11th | O4: 12th | P4: Year 1 | Q4: Year 2 | R4: Year 3
A5: Total number of New users | B5: =SUM('Customer Acquisition'!D38) -> 3952.2968 | C5: =SUM(B5*B7) -> 988.0742 | D5: =SUM(B5*C7) -> 1976.1484 | E5: =SUM(B5*D7) -> 2964.2226 | F5: =SUM(B5*E7) -> 3952.2968 | G5: =SUM(B5*F7) -> 10483.791 | H5: =SUM(B5*G7) -> 13437.753 | J5: =SUM(B5*H7) -> 14028.811 | K5: =SUM(B5*J7) -> 21297.582 | L5: =SUM(B5*K7) -> 31309.22 | M5: =SUM(B5*L7) -> 43748.909 | N5: =SUM(B5*M7) -> 56704.902 | O5: =SUM(B5*N7) -> 81727.756 | P5: =SUM(O11) -> 268488.49 | Q5: =SUM(P5*Q7) -> 536976.99 | R5: =SUM(Q5*R7) -> 1073954
A6: Total Active users | C6: =SUM(C12) -> 281.60115 | D6: =SUM(D12) -> 844.80344 | E6: =SUM(E12) -> 1689.6069 | F6: =SUM(F12) -> 2816.0115 | G6: =SUM(G12) -> 5803.892 | H6: =SUM(H12) -> 9633.6515 | J6: =SUM(J12) -> 13631.863 | K6: =SUM(K12) -> 19701.674 | L6: =SUM(L12) -> 28624.801 | M6: =SUM(M12) -> 41093.24 | N6: =SUM(N12) -> 57254.137 | O6: =SUM(O12) -> 80546.548 | P6: =SUM(P12) -> 80546.548 | Q6: =SUM(Q12) -> 241639.64 | R6: =SUM(R12) -> 563825.84
A7: Monthly Grow Rate | B7: 0.25 | C7: 0.5 | D7: 0.75 | E7: 1 | F7: =Max(0,E44) -> 2.652582 | G7: =Max(0,F44) -> 3.3999857 | H7: =Max(0,G44) -> 3.5495338 | J7: =Max(0,I44) -> 5.3886597 | K7: =Max(0,J44) -> 7.9217787 | L7: =Max(0,K44) -> 11.069237 | M7: =Max(0,L44) -> 14.347329 | N7: =Max(0,M44) -> 20.678547 | O7: =Max(0,N44) -> 25.578685 | Q7: 2 | R7: 2
A8: Churn Rate | C8: 0.05 | D8: 0.05 | E8: 0.05 | F8: 0.05 | G8: 0.05 | H8: 0.05 | J8: 0.05 | K8: 0.05 | L8: 0.05 | M8: 0.05 | N8: 0.05 | O8: 0.05
A9: Active Rate | C9: =SUM('Income Statement'!D4) -> 0.3 | D9: =SUM(C9) -> 0.3 | E9: =SUM(D9) -> 0.3 | F9: =SUM(E9) -> 0.3 | G9: =SUM(F9) -> 0.3 | H9: =SUM(G9) -> 0.3 | J9: =SUM(H9) -> 0.3 | K9: =SUM(J9) -> 0.3 | L9: =SUM(K9) -> 0.3 | M9: =SUM(L9) -> 0.3 | N9: =SUM(M9) -> 0.3 | O9: =SUM(N9) -> 0.3 | P9: =SUM(O9) -> 0.3 | Q9: =SUM(P9) -> 0.3 | R9: =SUM(Q9) -> 0.3
A10: Total Downloads | C10: =SUM(C5) -> 988.0742 | D10: =SUM(C10+D5) -> 2964.2226 | E10: =SUM(D10+E5) -> 5928.4452 | F10: =SUM(E10+F5) -> 9880.742 | G10: =SUM(F10+G5) -> 20364.533 | H10: =SUM(G10+H5) -> 33802.286 | J10: =SUM(H10+J5) -> 47831.097 | K10: =SUM(J10+K5) -> 69128.679 | L10: =SUM(K10+L5) -> 100437.9 | M10: =SUM(L10+M5) -> 144186.81 | N10: =SUM(M10+N5) -> 200891.71 | O10: =SUM(N10+O5) -> 282619.47
A11: Total User | C11: =SUM(C10-(C10*C8)) -> 938.67049 | D11: =SUM(D10-(D10*D8)) -> 2816.0115 | E11: =SUM(E10-(E10*E8)) -> 5632.0229 | F11: =SUM(F10-(F10*F8)) -> 9386.7049 | G11: =SUM(G10-(G10*G8)) -> 19346.307 | H11: =SUM(H10-(H10*H8)) -> 32112.172 | J11: =SUM(J10-(J10*J8)) -> 45439.542 | K11: =SUM(K10-(K10*K8)) -> 65672.245 | L11: =SUM(L10-(L10*L8)) -> 95416.005 | M11: =SUM(M10-(M10*M8)) -> 136977.47 | N11: =SUM(N10-(N10*N8)) -> 190847.12 | O11: =SUM(O10-(O10*O8)) -> 268488.49 | P11: =SUM(O11) -> 268488.49 | Q11: =SUM(P11+Q5) -> 805465.48 | R11: =SUM(Q11+R5) -> 1879419.5
A12: MAU | B12: 1 | C12: =SUM(C11*C9) -> 281.60115 | D12: =SUM(D11*D9) -> 844.80344 | E12: =SUM(E11*E9) -> 1689.6069 | F12: =SUM(F11*F9) -> 2816.0115 | G12: =SUM(G11*G9) -> 5803.892 | H12: =SUM(H11*H9) -> 9633.6515 | J12: =SUM(J11*J9) -> 13631.863 | K12: =SUM(K11*K9) -> 19701.674 | L12: =SUM(L11*L9) -> 28624.801 | M12: =SUM(M11*M9) -> 41093.24 | N12: =SUM(N11*N9) -> 57254.137 | O12: =SUM(O11*O9) -> 80546.548 | P12: =SUM(P11*P9) -> 80546.548 | Q12: =SUM(Q11*Q9) -> 241639.64 | R12: =SUM(R11*R9) -> 563825.84
A13: Number of new Business on app | B13: =SUM('Customer Acquisition'!D62) -> 158.33333 | C13: =SUM(B13*C14) -> 158.33333 | D13: =SUM(B13*D14) -> 158.33333 | E13: =SUM(B13*E14) -> 448.68399 | F13: =SUM(B13*F14) -> 406.22063 | G13: =SUM(B13*G14) -> 338.33226 | H13: =SUM(B13*H14) -> 349.54836 | I13: =SUM(B13*I14) -> 474.31683 | J13: =SUM(I13+(C13*3)) -> 949.31683 | K13: =SUM(D13*K14) -> 656.7014 | L13: =SUM(E13*L14) -> 2503.142 | M13: =SUM(F13*M14) -> 2871.7857 | N13: =SUM(G13*N14) -> 3365.9189 | O13: =SUM(H13*O14) -> 4256.3923 | P13: =SUM(C13:O13) -> 16937.026 | Q13: =P13+P13*Q14 -> 84685.13 | R13: =Q13+Q13*R14 -> 592795.91
A14: Annual Grow Rate | C14: 1 | D14: =Max(0,C49) -> 1 | E14: =Max(0,D49) -> 2.8337936 | F14: =Max(0,E49) -> 2.565604 | G14: =Max(0,F49) -> 2.1368353 | H14: =Max(0,G49) -> 2.2076739 | I14: =Max(0,H49) -> 2.9956853 | J14: =Max(0,H49) -> 2.9956853 | K14: =Max(0,J49) -> 4.1475878 | L14: =Max(0,K49) -> 5.5788529 | M14: =Max(0,L49) -> 7.0695222 | N14: =Max(0,M49) -> 9.9485604 | O14: =Max(0,N49) -> 12.176834 | P14: =AVERAGE(D14:O14) -> 4.6380529 | Q14: 4 | R14: =Q14*1.5 -> 6
A15: Churn rate | C15: 0.1 | D15: 0.1 | E15: 0.1 | F15: 0.1 | G15: 0.1 | H15: 0.1 | J15: 0.1 | K15: 0.1 | L15: 0.1 | M15: 0.1 | N15: 0.1 | O15: 0.1 | P15: 0.1 | Q15: 0.1 | R15: 0.1
A16: Paid Business Subscriber | C16: 0.1 | D16: 0.1 | E16: 0.2 | F16: 0.2 | G16: 0.2 | H16: 0.2 | J16: 0.3 | K16: 0.3 | L16: 0.3 | M16: 0.35 | N16: 0.35 | O16: 0.4
A17: No of City | C17: 1 | D17: 1 | E17: 1 | F17: 1 | G17: 1 | H17: 1 | J17: 4 | K17: 4 | L17: 4 | M17: 16 | N17: 16 | O17: 32 | P17: 64 | Q17: 120 | R17: 120
A18: Number of active new business users | C18: =C13-C13*C15 -> 142.5 | D18: =D13-D13*D15+C18 -> 285 | E18: =E13-E13*E15+D18 -> 688.81559 | F18: =F13-F13*F15+E18 -> 1054.4142 | G18: =G13-G13*G15+F18 -> 1358.9132 | H18: =H13-H13*H15+G18 -> 1673.5067 | J18: =J13-J13*J15+H18 -> 2527.8919 | K18: =K13-K13*K15+J18 -> 3118.9231 | L18: =L13-L13*L15+K18 -> 5371.7509 | M18: =M13-M13*M15+L18 -> 7956.3581 | N18: =N13-N13*N15+M18 -> 10985.685 | O18: =O13-O13*O15+N18 -> 14816.438 | P18: 39032.227 | Q18: =Q13-Q13*Q15+P18 -> 115248.84 | R18: =R13-R13*R15+Q18 -> 648765.16
A19: Commission on Sales | C19: =SUM(C6*Assumptions!C23*Assumptions!D23) -> 45760.186 | D19: =SUM(D6*Assumptions!C23*Assumptions!D23) -> 137280.56 | E19: =SUM(E6*Assumptions!C23*Assumptions!D23) -> 274561.12 | F19: =SUM(F6*Assumptions!C23*Assumptions!D23) -> 457601.86 | G19: =SUM(G6*Assumptions!C23*Assumptions!D23) -> 943132.45 | H19: =SUM(H6*Assumptions!C23*Assumptions!D23) -> 1565468.4 | J19: =SUM(J6*Assumptions!C23*Assumptions!D23) -> 2215177.7 | K19: =SUM(K6*Assumptions!C23*Assumptions!D23) -> 3201522 | L19: =SUM(L6*Assumptions!C23*Assumptions!D23) -> 4651530.2 | M19: =SUM(M6*Assumptions!C23*Assumptions!D23) -> 6677651.6 | N19: =SUM(N6*Assumptions!C23*Assumptions!D23) -> 9303797.3 | O19: =SUM(O6*Assumptions!C23*Assumptions!D23) -> 13088814 | P19: =SUM(C18:O19) -> 42612278 | Q19: =SUM(12*Q6*Assumptions!C23*Assumptions!D23) -> 4.7119731e+08 | R19: =SUM(12*R6*Assumptions!C23*Assumptions!D23) -> 1099460379
A20: Promoted Sales (5%) | C20: =SUM(C6*Assumptions!C24*Assumptions!D24) -> 18304.075 | D20: =SUM(D6*Assumptions!C24*Assumptions!D24) -> 54912.224 | E20: =SUM(E6*Assumptions!C24*Assumptions!D24) -> 109824.45 | F20: =SUM(F6*Assumptions!C24*Assumptions!D24) -> 183040.75 | G20: =SUM(G6*Assumptions!C24*Assumptions!D24) -> 377252.98 | H20: =SUM(H6*Assumptions!C24*Assumptions!D24) -> 626187.35 | J20: =SUM(J6*Assumptions!C24*Assumptions!D24) -> 886071.07 | K20: =SUM(K6*Assumptions!C24*Assumptions!D24) -> 1280608.8 | L20: =SUM(L6*Assumptions!C24*Assumptions!D24) -> 1860612.1 | M20: =SUM(M6*Assumptions!C24*Assumptions!D24) -> 2671060.6 | N20: =SUM(N6*Assumptions!C24*Assumptions!D24) -> 3721518.9 | O20: =SUM(O6*Assumptions!C24*Assumptions!D24) -> 5235525.6 | P20: =SUM(C20:O20) -> 17024919 | Q20: =SUM(12*Q6*Assumptions!C24*Assumptions!D24) -> 1.8847892e+08 | R20: =SUM(12*R6*Assumptions!C24*Assumptions!D24) -> 4.3978415e+08
A21: Business Subscription | B21: =SUM(Assumptions!E25) -> 1500 | C21: =SUM(B21*(C18*C16)) -> 21375 | D21: =SUM(B21*(D18*D16)) -> 42750 | E21: =SUM(B21*(E18*E16)) -> 206644.68 | F21: =SUM(B21*(F18*F16)) -> 316324.25 | G21: =SUM(B21*(G18*G16)) -> 407673.96 | H21: =SUM(B21*(H18*H16)) -> 502052.02 | J21: =SUM(B21*(J18*J16)) -> 1137551.3 | K21: =SUM(B21*(K18*K16)) -> 1403515.4 | L21: =SUM(B21*(L18*L16)) -> 2417287.9 | M21: =SUM(B21*(M18*M16)) -> 4177088 | N21: =SUM(B21*(N18*N16)) -> 5767484.7 | O21: =SUM(B21*(O18*O16)) -> 8889862.9 | P21: =SUM(C21:O21) -> 25289610 | Q21: =SUM(12*Q18*500) -> 6.9149306e+08 | R21: =SUM(12*R18*500) -> 3892590961
A22: Cash Store Afilates Commission | C22: =SUM(C6*Assumptions!C26*Assumptions!D26) -> 2816.0115 | D22: =SUM(D6*Assumptions!C26*Assumptions!D26) -> 8448.0344 | E22: =SUM(E6*Assumptions!C26*Assumptions!D26) -> 16896.069 | F22: =SUM(F6*Assumptions!C26*Assumptions!D26) -> 28160.115 | G22: =SUM(G6*Assumptions!C26*Assumptions!D26) -> 58038.92 | H22: =SUM(H6*Assumptions!C26*Assumptions!D26) -> 96336.515 | J22: =SUM(J6*Assumptions!C26*Assumptions!D26) -> 136318.63 | K22: =SUM(K6*Assumptions!C26*Assumptions!D26) -> 197016.74 | L22: =SUM(L6*Assumptions!C26*Assumptions!D26) -> 286248.01 | M22: =SUM(M6*Assumptions!C26*Assumptions!D26) -> 410932.4 | N22: =SUM(N6*Assumptions!C26*Assumptions!D26) -> 572541.37 | O22: =SUM(O6*Assumptions!C26*Assumptions!D26) -> 805465.48 | P22: =SUM(C22:O22) -> 2619218.3 | Q22: =SUM(12*Q6*Assumptions!C26*Assumptions!D26) -> 28996757 | R22: =SUM(12*R6*Assumptions!C26*Assumptions!D26) -> 67659100
A23: Subscription | C23: =SUM(C6*49) -> 13798.456 | D23: =SUM(D6*49) -> 41395.369 | E23: =SUM(E6*49) -> 82790.737 | F23: =SUM(F6*49) -> 137984.56 | G23: =SUM(G6*49) -> 284390.71 | H23: =SUM(H6*49) -> 472048.92 | J23: =SUM(J6*49) -> 667961.27 | K23: =SUM(K6*49) -> 965382.01 | L23: =SUM(L6*49) -> 1402615.3 | M23: =SUM(M6*49) -> 2013568.8 | N23: =SUM(N6*49) -> 2805452.7 | O23: =SUM(O6*49) -> 3946780.8 | P23: =SUM(C23:O23) -> 12834170 | Q23: =SUM(12*Q12*49) -> 1.4208411e+08 | R23: =SUM(12*R12*49) -> 3.3152959e+08
A24: Total Revenue | B24: 1 | C24: =SUM(C19:C23) -> 102053.73 | D24: =SUM(D19:D23) -> 284786.19 | E24: =SUM(E19:E23) -> 690717.05 | F24: =SUM(F19:F23) -> 1123111.5 | G24: =SUM(G19:G23) -> 2070489 | H24: =SUM(H19:H23) -> 3262093.2 | J24: =SUM(J19:J23) -> 5043080 | K24: =SUM(K19:K23) -> 7048044.9 | L24: =SUM(L19:L23) -> 10618294 | M24: =SUM(M19:M23) -> 15950301 | N24: =SUM(N19:N23) -> 22170795 | O24: =SUM(O19:O23) -> 31966449 | P24: =SUM(C24:O24) -> 1.0033021e+08 | Q24: =SUM(Q19:Q23) -> 1522250155 | R24: =SUM(R19:R23) -> 5831024183
A26: Expenses | I26: Next Phase Estimate
A27: Rent and office Expenses | B27: =SUM(C27) -> 66666.667 | C27: =median(50000,Assumptions!B10,200000) -> 66666.667 | D27: =SUM(C27) -> 66666.667 | E27: =SUM(D27) -> 66666.667 | F27: =SUM(E27) -> 66666.667 | G27: =SUM(F27) -> 66666.667 | H27: =SUM(G27) -> 66666.667 | I27: =SUM(H27+(C27*3)) -> 266666.67 | J27: =median(200000,Assumptions!F10+I27,800000) -> 280000 | K27: =SUM(J27) -> 280000 | L27: =SUM(K27) -> 280000 | M27: =SUM(L27*4) -> 1120000 | N27: =SUM(M27*4) -> 4480000 | O27: =SUM(N27*4) -> 17920000 | P27: =SUM(B27:O27) -> 25093333 | Q27: =SUM(12*P27*2) -> 602240000 | R27: =SUM(Q27) -> 602240000
A28: Team Building & Legal | B28: =SUM(C28) -> 66666.667 | C28: =MEDIAN(50000,Assumptions!B11, 300000) -> 66666.667 | D28: =SUM(C28) -> 66666.667 | E28: =SUM(D28) -> 66666.667 | F28: =SUM(E28*1.5) -> 100000 | G28: =SUM(F28) -> 100000 | H28: =SUM(G28) -> 100000 | I28: =SUM(H28+(C28*3)) -> 300000 | J28: =MEDIAN(150000,Assumptions!F11+I28, 900000) -> 313333.33 | K28: =SUM(J28) -> 313333.33 | L28: =SUM(K28*1.5) -> 470000 | M28: =SUM(L28*1.5) -> 705000 | N28: =SUM(M28*1.5) -> 1057500 | O28: =SUM(N28) -> 1057500 | P28: =SUM(B28:O28) -> 4783333.3 | Q28: =SUM(12*P28*2) -> 114800000 | R28: =SUM(Q28*2) -> 229600000
A29: Customer Support Costs | B29: =SUM(C29) -> 66666.667 | C29: =MIN(500000,Assumptions!B12) -> 66666.667 | D29: =SUM(C29) -> 66666.667 | E29: =SUM(D29) -> 66666.667 | F29: =SUM(E29*1.5) -> 100000 | G29: =SUM(F29) -> 100000 | H29: =SUM(G29) -> 100000 | I29: =SUM(H29+(C29*3)) -> 300000 | J29: =MEDIAN(150000,Assumptions!F12+I29, 900000) -> 313333.33 | K29: =SUM(J29) -> 313333.33 | L29: =SUM(K29*1.5) -> 470000 | M29: =SUM(L29*1.5) -> 705000 | N29: =SUM(M29*1.5) -> 1057500 | O29: =SUM(N29) -> 1057500 | P29: =SUM(B29:O29) -> 4783333.3 | Q29: =SUM(12*P29*2) -> 114800000 | R29: =SUM(Q29*2) -> 229600000
A30: Technology & Infrastructure Costs | B30: =SUM(C30) -> 166666.67 | C30: =SUM(Assumptions!B13) -> 166666.67 | D30: =SUM(C30) -> 166666.67 | E30: =SUM(D30) -> 166666.67 | F30: =SUM(E30*2) -> 333333.33 | G30: =SUM(F30) -> 333333.33 | H30: =SUM(G30) -> 333333.33 | I30: =SUM(H30) -> 333333.33 | J30: =MEDIAN(150000,Assumptions!H13, 1500000) -> 366666.67 | K30: =SUM(J30) -> 366666.67 | L30: =SUM(K30*1.5) -> 550000 | M30: =SUM(L30*1.5) -> 825000 | N30: =SUM(M30*1.5) -> 1237500 | O30: =SUM(N30) -> 1237500 | P30: =SUM(B30:O30) -> 6583333.3 | Q30: =SUM(12*P30*2) -> 158000000 | R30: =SUM(Q30*2) -> 316000000
A31: Business Development & Partnerships | B31: =SUM('Customer Acquisition'!C60) -> 1000 | C31: =SUM(B31*C13) -> 158333.33 | D31: =SUM(B31*D13) -> 158333.33 | E31: =SUM(B31*E13) -> 448683.99 | F31: =SUM(B31*F13) -> 406220.63 | G31: =SUM(B31*G13) -> 338332.26 | H31: =SUM(B31*H13) -> 349548.36 | I31: =SUM(B31*I13) -> 474316.83 | J31: =SUM(Assumptions!H14) -> 505983.5 | K31: =SUM(B31*K13) -> 656701.4 | L31: =SUM(B31*L13) -> 2503142 | M31: =SUM(B31*M13) -> 2871785.7 | N31: =SUM(B31*N13) -> 3365918.9 | O31: =SUM(B31*O13) -> 4256392.3 | P31: =SUM(B31:O31) -> 16494693 | Q31: =SUM(12*P31*2) -> 3.9587262e+08 | R31: =SUM(Q31*2) -> 7.9174524e+08
A32: Marketing & User Acquisition: | B32: =SUM(B43) -> 300000 | C32: =SUM(C43) -> 300000 | D32: =SUM(D43) -> 300000 | E32: =SUM(E43) -> 300000 | F32: =SUM(E43+E39) -> 795774.59 | G32: =SUM(F43+F39) -> 1019995.7 | H32: =SUM(G43+G39) -> 1064860.1 | I32: =SUM(H43+H39) -> 1879917.5 | J32: =SUM(Assumptions!H15) -> 1939917.5 | K32: =SUM(J43+J39) -> 2851840.3 | L32: =SUM(K43+K39) -> 3984925.2 | M32: =SUM(L43+L39) -> 5165038.4 | N32: =SUM(M43+M39) -> 7444277 | O32: =SUM(N43+N39) -> 9208326.6 | P32: =SUM(B32:O32) -> 36554873 | Q32: =SUM(12*P32*2) -> 8.7731695e+08 | R32: =SUM(Q32*2) -> 1754633901
A34: Total Expenses | B34: =SUM(B27:B32) -> 667666.67 | C34: =SUM(C27:C32) -> 825000 | D34: =SUM(D27:D32) -> 825000 | E34: =SUM(E27:E32) -> 1115350.7 | F34: =SUM(F27:F32) -> 1801995.2 | G34: =SUM(G27:G32) -> 1958328 | H34: =SUM(H27:H32) -> 2014408.5 | J34: =SUM(J27:J32) -> 3719234.3 | K34: =SUM(K27:K32) -> 4781875 | L34: =SUM(L27:L32) -> 8258067.2 | M34: =SUM(M27:M32) -> 11391824 | N34: =SUM(N27:N32) -> 18642696 | O34: =SUM(O27:O32) -> 34737219 | P34: =SUM(P27:P32) -> 94292899 | Q34: =SUM(Q30) -> 158000000 | R34: =SUM(R30) -> 316000000
A35: Net | B35: =SUM(B24-B34) -> -667665.67 | C35: =SUM(C24-C34) -> -722946.27 | D35: =SUM(D24-D34) -> -540213.81 | E35: =SUM(E24-E34) -> -424633.61 | F35: =SUM(F24-F34) -> -678883.69 | G35: =SUM(G24-G34) -> 112161.04 | H35: =SUM(H24-H34) -> 1247684.7 | J35: =SUM(J24-J34) -> 1323845.6 | K35: =SUM(K24-K34) -> 2266169.8 | L35: =SUM(L24-L34) -> 2360226.3 | M35: =SUM(M24-M34) -> 4558477.3 | N35: =SUM(N24-N34) -> 3528099.1 | O35: =SUM(O24-O34) -> -2770769.9 | P35: =SUM(P24-P34) -> 6037315.5 | Q35: =SUM(Q24-Q34) -> 1364250155 | R35: =SUM(R24-R34) -> 5515024183
A37: Cash In hand (if budget is fixed) | B37: =SUM((B24+Assumptions!B8)-B34) -> 4332334.3 | C37: =SUM((C24+Assumptions!B8)-C34) -> 4277053.7 | D37: =SUM(((D24+Assumptions!C8)-D34)+C37) -> 3736839.9 | E37: =SUM(((E24+Assumptions!H26)-E34)+D37) -> 3312206.3 | F37: =SUM(((F24+Assumptions!I26)-F34)+E37) -> 2633322.6 | G37: =SUM(((G24+Assumptions!J26)-G34)+F37) -> 2745483.6 | H37: =SUM(((H24+Assumptions!G8)-H34)+G37) -> 3993168.3 | I37: =SUM(H37+Assumptions!F6) -> 4493168.3 | J37: =SUM(((J24+Assumptions!H8)-J34)+I37) -> 5817014 | K37: =SUM(((K24+Assumptions!K8)-K34)+J37) -> 8083183.8 | L37: =SUM(((L24+Assumptions!L8)-L34)+K37) -> 10443410 | M37: =SUM(((M24+Assumptions!M8)-M34)+L37) -> 15001887 | N37: =SUM(((N24+Assumptions!N8)-N34)+M37) -> 18529986 | O37: =SUM(((O24+Assumptions!O8)-O34)+N37) -> 15759217 | P37: =SUM(((P24+Assumptions!P8)-P34)+O37) -> 21796532 | Q37: =SUM(((Q24+Assumptions!Q8)-Q34)+P37) -> 1386046687 | R37: =SUM(((R24+Assumptions!R8)-R34)+Q37) -> 6901070870
A38: Surplus cash (can be used for next month) | D38: =SUM(D37-Assumptions!B9) -> 2903506.6 | E38: =SUM(E37-Assumptions!B9) -> 2478873 | F38: =SUM(F37-Assumptions!B9) -> 1799989.3 | G38: =SUM(G37-Assumptions!B9) -> 1912150.3 | H38: =SUM(H37-Assumptions!B9) -> 3159835 | I38: =SUM(H38) -> 3159835 | J38: =SUM(J37-Assumptions!B9) -> 4983680.6 | K38: =SUM(K37-Assumptions!B9) -> 7249850.5 | L38: =SUM(L37-Assumptions!B9) -> 9610076.8 | M38: =SUM(M37-Assumptions!B9) -> 14168554 | N38: =SUM(N37-Assumptions!B9) -> 17696653 | O38: =SUM(O37-Assumptions!B9) -> 14925883 | P38: =SUM(P37-50000000) -> -28203468 | Q38: =SUM(Q37-50000000) -> 1336046687 | R38: =SUM(R37-50000000) -> 6851070870
A39: Additional budget for Markeitng (next month) | E39: =MAX(0,E43*E45) -> 495774.59 | F39: =MAX(0,F43*F45) -> 719995.71 | G39: =MAX(0,G43*G45) -> 764860.13 | H39: =MAX(0,H43*H45) -> 1579917.5 | I39: =MAX(0,I43*I45) -> 1579917.5 | J39: =MAX(0,J43*J45) -> 2491840.3 | K39: =MAX(0,K43*K45) -> 3624925.2 | L39: =MAX(0,L43*L45) -> 4805038.4 | ... O39: =MAX(0,O43*O45) -> 7462941.6 | P39: =SUM(P43*P45) -> -19742428 | Q39: =SUM(Q43*Q45) -> 9.3523268e+08 | R39: =SUM(R43*R45) -> 4795749609
A40: Additional budget for BD (next month) | D40: =MAX(0,D48*D50) -> 290350.66 | E40: =MAX(0,E48*E50) -> 247887.3 | F40: =MAX(0,F48*F50) -> 179998.93 | G40: =MAX(0,G48*G50) -> 191215.03 | H40: =MAX(0,H48*H50) -> 315983.5 | I40: =MAX(0,I48*I50) -> 315983.5 | J40: =MAX(0,J48*J50) -> 498368.06 | K40: =MAX(0,K48*K50) -> 724985.05 | ... O40: =MAX(0,O48*O50) -> 1492588.3
A41: Final Cash Left (after additional use) | B41: =SUM(B37-(B38*B46)) -> 4332334.3 | C41: =SUM(C37-(C38*C46)) -> 4277053.7 | D41: =SUM(D37-(D38*D46)) -> 3736839.9 | E41: =SUM((D41+E24)-E34) -> 3312206.3 | F41: =SUM((E41+F24)-F34) -> 2633322.6 | G41: =SUM((F41+G24)-G34) -> 2745483.6 | H41: =SUM((G41+H24)-H34) -> 3993168.3 | I41: =SUM(H41+Assumptions!F6) -> 4493168.3 | J41: =SUM((I41+J24)-J34) -> 5817014 | K41: =SUM((J41+K24)-K34) -> 8083183.8 | L41: =SUM((K41+L24)-L34) -> 10443410 | M41: =SUM((L41+M24)-M34) -> 15001887 | N41: =SUM((M41+N24)-N34) -> 18529986 | O41: =SUM((N41+O24)-O34) -> 15759217
A43: Marketing budget Fixed | B43: =SUM('Customer Acquisition'!B38) -> 300000 | C43: =SUM(B43) -> 300000 | D43: =SUM(C43) -> 300000 | E43: =SUM(D43) -> 300000 | F43: =SUM(E43) -> 300000 | G43: =SUM(F43) -> 300000 | H43: =SUM(G43) -> 300000 | I43: =SUM(H43+Assumptions!F15) -> 360000 | J43: =SUM(I43) -> 360000 | K43: =SUM(J43) -> 360000 | L43: =SUM(K43) -> 360000 | M43: =SUM(L43) -> 360000 | N43: =SUM(M43) -> 360000 | O43: =SUM(N43) -> 360000 | P43: =SUM(O43) -> 360000 | Q43: =SUM(P43) -> 360000 | R43: =SUM(Q43) -> 360000
B44: =SUM(1+(B45)) -> 1 | C44: =SUM(1+(C45)) -> 1 | D44: =SUM(1+(D45)) -> 8.7426842 | E44: =SUM(1+(E45)) -> 2.652582 | F44: =SUM(1+(F45)) -> 3.3999857 | G44: =SUM(1+(G45)) -> 3.5495338 | H44: =SUM(1+(H45)) -> 6.2663916 | I44: =SUM(1+(I45)) -> 5.3886597 | ... O44: =SUM(1+(O45)) -> 21.730393
A45: Additional budget for Markeitng ( multiple) | B45: =SUM((B38*0.8)/B43) -> 0 | C45: =SUM((C38*0.8)/C43) -> 0 | D45: =SUM((D38*0.8)/D43) -> 7.7426842 | E45: =max(0,(E38*E46)/E43) -> 1.652582 | F45: =max(0,(F38*F46)/F43) -> 2.3999857 | G45: =max(0,(G38*G46)/G43) -> 2.5495338 | H45: =max(0,(H38*H46)/H43) -> 5.2663916 | I45: =max(0,(I38*I46)/I43) -> 4.3886597 | J45: =max(0,(J38*J46)/J43) -> 6.9217787 | K45: =max(0,(K38*K46)/K43) -> 10.069237 | L45: =max(0,(L38*L46)/L43) -> 13.347329 | ... O45: =max(0,(O38*O46)/O43) -> 20.730393 | P45: =SUM((P38*0.7)/P43) -> -54.840077 | Q45: =SUM((Q38*0.7)/Q43) -> 2597.8686 | R45: =SUM((R38*0.7)/R43) -> 13321.527
...

Sheet Income Statement
A1: Financials
A2: Income statement projection
B3: ( values in ₹) | C3: AOV | D3: 650
C4: ACU | D4: 0.3
B5: Year 1 | C5: Year 2 | D5: Year 3
A6: Revenue
A7: Commission on Sales | B7: =SUM('Monthly BrakeDown'!P19) -> 42612278 | C7: ='Monthly BrakeDown'!Q19 -> 4.7119731e+08 | D7: ='Monthly BrakeDown'!R19 -> 1099460379
A8: Promoted Sales (5%) | B8: ='Monthly BrakeDown'!P20 -> 17024919 | C8: ='Monthly BrakeDown'!Q20 -> 1.8847892e+08 | D8: ='Monthly BrakeDown'!R20 -> 4.3978415e+08
A9: Business Subscription | B9: ='Monthly BrakeDown'!P21 -> 25289610 | C9: ='Monthly BrakeDown'!Q21 -> 6.9149306e+08 | D9: ='Monthly BrakeDown'!R21 -> 3892590961
A10: Affiliate | B10: =SUM('Monthly BrakeDown'!P22) -> 2619218.3 | C10: =SUM('Monthly BrakeDown'!Q22) -> 28996757 | D10: =SUM('Monthly BrakeDown'!R22) -> 67659100
A11: Subscription | B11: =SUM('Monthly BrakeDown'!P23) -> 12834170 | C11: =SUM('Monthly BrakeDown'!Q23) -> 1.4208411e+08 | D11: =SUM('Monthly BrakeDown'!R23) -> 3.3152959e+08
A12: Finance
A13: B2B Buying | C13: =SUM(Assumptions!C29*Assumptions!D29*Assumptions!F29) -> 11524884 | D13: =SUM(Assumptions!C29*Assumptions!D29*Assumptions!G29) -> 129753032
A15: Total Revenue | B15: =SUM(B7:B14) -> 1.0038019e+08 | C15: =SUM(C7:C14) -> 1533775039 | D15: =SUM(D7:D14) -> 5960777215
A16: Expenses
A17: Technology & Infrastructure Costs | B17: =SUM(Assumptions!C32) -> 6583333.3 | C17: =SUM(Assumptions!D32) -> 158000000 | D17: =SUM(Assumptions!E32) -> 316000000
A18: Marketing & User Acquisition: | B18: =SUM(Assumptions!C33) -> 36554873 | C18: =SUM(Assumptions!D33) -> 8.7731695e+08 | D18: =SUM(Assumptions!E33) -> 1754633901
A19: Business Development & Partnerships | B19: =SUM(Assumptions!C34) -> 16494693 | C19: =SUM(Assumptions!D34) -> 3.9587262e+08 | D19: =SUM(Assumptions!E34) -> 7.9174524e+08
A20: Customer Support Costs | B20: =SUM(Assumptions!C35) -> 4783333.3 | C20: =SUM(Assumptions!D35) -> 114800000 | D20: =SUM(Assumptions!E35) -> 229600000
A21: Team Building & Legal | B21: =SUM(Assumptions!C36) -> 4783333.3 | C21: =SUM(Assumptions!D36) -> 114800000 | D21: =SUM(Assumptions!E36) -> 229600000
A22: Rent and office Expenses | B22: =SUM(Assumptions!C37) -> 25093333 | C22: =SUM(Assumptions!D37) -> 602240000 | D22: =SUM(Assumptions!E37) -> 602240000
A24: Total User | B24: =SUM('Monthly BrakeDown'!P5) -> 268488.49 | C24: =SUM('Monthly BrakeDown'!Q5) -> 536976.99 | D24: =SUM('Monthly BrakeDown'!R5) -> 1073954
A25: Total Active User | B25: =SUM('Monthly BrakeDown'!P6) -> 80546.548 | C25: =SUM('Monthly BrakeDown'!Q6) -> 241639.64 | D25: =SUM('Monthly BrakeDown'!R6) -> 563825.84
A26: CAC | B26: =SUM(B18/B24) -> 136.15061 | C26: =SUM(C18/C24) -> 1633.8074 | D26: =SUM(D18/D24) -> 1633.8074
A27: CAC (Active User) | B27: =SUM(B18/B25) -> 453.83538 | C27: =SUM(C18/C25) -> 3630.683 | D27: =SUM(D18/D25) -> 3112.014
A28: Annual ARPU | B28: ₹5,814.32 | C28: ₹879.71 | D28: ₹785.90
A29: Payback Period | B29: =Assumptions!C51 | C29: =Assumptions!D51 | D29: =Assumptions!E51
B31: =Assumptions!C52 | C31: =Assumptions!D52 | D31: =Assumptions!E52
A32: Total expenses | B32: =SUM(B17:B22) -> 94292899 | C32: =SUM(C17:C22) -> 2263029573 | D32: =SUM(D17:D22) -> 3923819146
A34: Gross Earning before taxes | B34: =SUM(B15-B32) -> 6087295.7 | C34: =SUM(C15-C32) -> -7.2925453e+08 | D34: =SUM(D15-D32) -> 2036958070
A35: Taxes | B35: =Max(0,B34*Assumptions!C3) -> 1826188.7 | C35: =Max(0,C34*Assumptions!D3) -> 0 | D35: =D34*Assumptions!C3 -> 611087421
A36: Net Profit after tax | B36: =B34-B35 -> 4261107 | C36: =C34-C35 -> -7.2925453e+08 | D36: =D34-D35 -> 1425870649
A37: Profitability | B37: =B36/B15 -> 0.042449679 | C37: =C36/C15 -> -0.47546382 | D37: =D36/D15 -> 0.23920885
A39: EBITDA | B39: =B36+B35 -> 6087295.7 | C39: =C36+C35 -> -7.2925453e+08 | D39: =D36+D35 -> 2036958070
B40: =B39/B15 -> 0.060642398 | C40: =C39/C15 -> -0.47546382 | D40: =D39/D15 -> 0.34172693
A41: Valuation (INR) | B41: =SUM(B15*20) -> 2007603892 | C41: =SUM(C15*10) -> 15337750391 | D41: =SUM(D15*10) -> 59607772155
A42: USD | B42: =SUM(B41/85) -> 23618869 | C42: =SUM(C41/85) -> 1.8044412e+08 | D42: =SUM(D41/85) -> 7.0126791e+08
A44: Total Downloads | B44: =SUM('Monthly BrakeDown'!P11) -> 268488.49 | C44: =SUM('Monthly BrakeDown'!Q11) -> 805465.48 | D44: =SUM('Monthly BrakeDown'!R11) -> 1879419.5
A46: Fixed Cost
A47: Variable Cost
...

Sheet Assumptions
A1: Assumptions
A2: Income Statement ( values in INR )
A3: Taxes | C3: 0.3
B4: Phase 1 | D4: Phase 2
D5: Cash | F5: Funding
A6: Funding | B6: 0 | F6: 500000 | G6: Total | H6: =SUM(F6+D7) -> 3762093.2
A7: Cash | B7: 5000000 | D7: =SUM('Monthly BrakeDown'!H24) -> 3262093.2 | E7: Total | F7: =SUM(F6/3) -> 166666.67 | G7: Monthly | H7: =SUM(H6/3) -> 1254031.1
A8: Total investment | B8: =SUM(B7) -> 5000000 | D8: =SUM(D7) -> 3262093.2
A9: Monthky (6 month) | B9: =SUM(B8/6) -> 833333.33 | D9: =SUM(D8/3) -> 1087364.4 | E9: Monthly
A10: Rent and office Expenses | B10: =SUM(B9*C10) -> 66666.667 | C10: 0.08 | D10: =SUM('Monthly BrakeDown'!I27) -> 266666.67 | E10: 0.1 | F10: =SUM(F7*G10) -> 13333.333 | G10: 0.08 | H10: =SUM(D10+F10) -> 280000
A11: Team Building & Legal | B11: =SUM(B9*C11) -> 66666.667 | C11: 0.08 | D11: =SUM('Monthly BrakeDown'!I28) -> 300000 | E11: 0.12 | F11: =SUM(F7*G11) -> 13333.333 | G11: 0.08 | H11: =SUM(D11+F11) -> 313333.33
A12: Customer Support Costs | B12: =SUM(B9*C12) -> 66666.667 | C12: 0.08 | D12: =SUM('Monthly BrakeDown'!I29) -> 300000 | E12: 0.1 | F12: =SUM(F7*G12) -> 13333.333 | G12: 0.08 | H12: =SUM(D12+F12) -> 313333.33
A13: Technology & Infrastructure Costs | B13: =SUM(B9*C13) -> 166666.67 | C13: 0.2 | D13: =SUM('Monthly BrakeDown'!I30) -> 333333.33 | E13: =SUM(D13/D9) -> 0.30655164 | F13: =SUM(F7*G13) -> 33333.333 | G13: 0.2 | H13: =SUM(D13+F13) -> 366666.67
A14: Business Development & Partnerships | B14: =SUM(B9*C14) -> 158333.33 | C14: 0.19 | D14: =SUM('Monthly BrakeDown'!I31) -> 474316.83 | E14: 0.13 | F14: =SUM(F7*G14) -> 31666.667 | G14: 0.19 | H14: =SUM(D14+F14) -> 505983.5
A15: Marketing & User Acquisition: | B15: =SUM(B9*C15) -> 300000 | C15: 0.36 | D15: =SUM('Monthly BrakeDown'!I32) -> 1879917.5 | E15: =SUM(D15/D13) -> 5.6397525 | F15: =SUM(F7*G15) -> 60000 | G15: 0.36 | H15: =SUM(D15+F15) -> 1939917.5
A16: Buffer | B16: =SUM(B13*C16) -> 1666.6667 | C16: 0.01 | D16: =SUM('Monthly BrakeDown'!I33) -> 0 | E16: 0.05 | F16: =SUM(F7*G16) -> 1666.6667 | G16: 0.01 | H16: =SUM(D16+F16) -> 1666.6667
A19: User (per multiple of budget) | B19: =SUM('Customer Acquisition'!J33) -> 23295.167
A20: Order Value | B20: =SUM('Income Statement'!D3) -> 650
A21: Active User | B21: =SUM('Income Statement'!D4) -> 0.3
A22: Source of Revenu | B22: GMV | C22: Revenue | D22: # per month | E22: Total | F22: Total GMV per user
A23: Commission on Sales (5%) | B23: =SUM(B20) -> 650 | C23: =SUM(B23*0.05) -> 32.5 | D23: 5 | E23: =SUM(C23*D23) -> 162.5 | F23: =SUM(B23*D23) -> 3250
A24: Promoted Sales (5%) | B24: =SUM(B20) -> 650 | C24: =SUM(B24*0.05) -> 32.5 | D24: 2 | E24: =SUM(C24*D24) -> 65
A25: Business Subscription | C25: 1500 | D25: 1 | E25: =SUM(C25*D25) -> 1500
A26: Cash Store Afilates Commission | B26: 50 | C26: =SUM(B26*0.1) -> 5 | D26: 2 | E26: =SUM(C26*D26) -> 10
A27: User Subscription | C27: 49 | D27: 1 | E27: =SUM(C27*D27) -> 49
A28: Finance
A29: B2B Buying | C29: 500 | D29: 2 | E29: 10% of seller | F29: =SUM('Monthly BrakeDown'!Q18*0.1) -> 11524.884 | G29: =SUM('Monthly BrakeDown'!R18*0.2) -> 129753.03
A31: Expenses | C31: Year 1 | D31: Year 2 | E31: Year 3 | F31: Growth Rate
A32: Technology & Infrastructure Costs | C32: =SUM('Monthly BrakeDown'!P30) -> 6583333.3 | D32: =SUM('Monthly BrakeDown'!Q30) -> 158000000 | E32: =SUM('Monthly BrakeDown'!R30) -> 316000000
A33: Marketing & User Acquisition: | C33: =SUM('Monthly BrakeDown'!P32) -> 36554873 | D33: =SUM('Monthly BrakeDown'!Q32) -> 8.7731695e+08 | E33: =SUM('Monthly BrakeDown'!R32) -> 1754633901
A34: Business Development & Partnerships | C34: =SUM('Monthly BrakeDown'!P31) -> 16494693 | D34: =SUM('Monthly BrakeDown'!Q31) -> 3.9587262e+08 | E34: =SUM('Monthly BrakeDown'!R31) -> 7.9174524e+08
A35: Customer Support Costs | C35: =SUM('Monthly BrakeDown'!P29) -> 4783333.3 | D35: =SUM('Monthly BrakeDown'!Q29) -> 114800000 | E35: =SUM('Monthly BrakeDown'!R29) -> 229600000
A36: Team Building & Legal | C36: =SUM('Monthly BrakeDown'!P28) -> 4783333.3 | D36: =SUM('Monthly BrakeDown'!Q28) -> 114800000 | E36: =SUM('Monthly BrakeDown'!R28) -> 229600000
A37: Rent and office Expenses | C37: =SUM('Monthly BrakeDown'!P27) -> 25093333 | D37: =SUM('Monthly BrakeDown'!Q27) -> 602240000 | E37: =SUM('Monthly BrakeDown'!R27) -> 602240000
A39: Valuation (USD) | C39: =SUM('Income Statement'!B42) -> 23618869 | D39: =SUM('Income Statement'!C42) -> 1.8044412e+08 | E39: =SUM('Income Statement'!D42) -> 7.0126791e+08
A40: Total User

Sheet Customer Acquisition
F1: Budget | G1: no of | H1: Total Budget | I1: CAC | J1: New User
A3: Channel | B3: PAID ADS (META / GOOGLE) | C3: Meta app install ads | D3: 100000 | E3: 1 | F3: =SUM(D3*E3) -> 100000 | G3: 1 | H3: =SUM(F3*G3) -> 100000 | I3: 300 | J3: =SUM(H3/I3) -> 333.33333
C4: Google UAC | D4: 100000 | E4: 1 | F4: =SUM(D4*E4) -> 100000 | G4: 1 | H4: =SUM(F4*G4) -> 100000 | I4: 300 | J4: =SUM(H4/I4) -> 333.33333
B5: College Events & Campus Programs | C5: College Business Fest | D5: 200000 | E5: 1 | F5: =SUM(D5*E5) -> 200000 | G5: 1 | H5: =SUM(F5*G5) -> 200000 | I5: 66.666667 | J5: =SUM(H5/I5) -> 3000
C6: College Sports Fest | D6: 1000000 | E6: 1 | F6: =SUM(D6*E6) -> 1000000 | G6: 0.25 | H6: =SUM(F6*G6) -> 250000 | I6: 100 | J6: =SUM(H6/I6) -> 2500
C7: Campus ambassadors | D7: 3000 | E7: 1 | F7: =SUM(D7*E7) -> 3000 | G7: =SUM(G5) -> 1 | H7: =SUM(F7*G7) -> 3000 | I7: 30 | J7: =SUM(H7/I7) -> 100
C8: On-ground QR onboarding | D8: 1000 | E8: 1 | F8: =SUM(D8*E8) -> 1000 | G8: 1 | H8: =SUM(F8*G8) -> 1000 | I8: 10 | J8: =SUM(H8/I8) -> 100
E9: 1 | F9: =SUM(D9*E9) -> 0
B10: Merchant-led Acquisition | C10: “Pay with ReZ & Earn Cashback” boards | D10: 1500 | E10: 1 | F10: =SUM(D10*E10) -> 1500 | G10: =SUM('Monthly BrakeDown'!C18) -> 142.5 | H10: =SUM(F10*G10) -> 213750 | I10: 50 | J10: =SUM(H10/I10) -> 4275
C11: QR on bills / counters | D11: 300 | E11: 1 | F11: =SUM(D11*E11) -> 300 | G11: =SUM(G10) -> 142.5 | H11: =SUM(F11*G11) -> 42750 | I11: 50 | J11: =SUM(H11/I11) -> 855
C12: Merchant staff push (refferal) | D12: 1000 | E12: 1 | F12: =SUM(D12*E12) -> 1000 | G12: =SUM(G11) -> 142.5 | H12: =SUM(F12*G12) -> 142500 | I12: 100 | J12: =SUM(H12/I12) -> 1425
C13: Scan & earn coins | D13: 50 | E13: 1 | F13: =SUM(D13*E13) -> 50 | G13: =SUM(G12) -> 142.5 | H13: =SUM(F13*G13) -> 7125 | I13: 50 | J13: =SUM(H13/I13) -> 142.5
B15: Referral Programs | C15: User referral (coins) | D15: 100 | E15: 1 | F15: =SUM(D15*E15) -> 100 | G15: 1 | H15: =SUM(F15*G15) -> 100 | I15: 100 | J15: =SUM(H15/I15) -> 1
B17: Influencer & Creator Marketing | C17: Instagram reels | D17: 1000 | E17: 1 | F17: =SUM(D17*E17) -> 1000 | G17: =SUM(G5*100) -> 100 | H17: =SUM(F17*G17) -> 100000 | I17: 100 | J17: =SUM(H17/I17) -> 1000
C18: College creators | D18: 1000 | E18: 1 | F18: =SUM(D18*E18) -> 1000 | G18: =SUM(G5*100) -> 100 | H18: =SUM(F18*G18) -> 100000 | I18: 100 | J18: =SUM(H18/I18) -> 1000
C19: Hyperlocal food & lifestyle pages | D19: 5000 | E19: 1 | F19: =SUM(D19*E19) -> 5000 | G19: 10 | H19: =SUM(F19*G19) -> 50000 | I19: 100 | J19: =SUM(H19/I19) -> 500
B20: Flea Markets, Pop-ups & Community Events | C20: Flea markets | D20: 100000 | E20: 1 | F20: =SUM(D20*E20) -> 100000 | G20: 1 | H20: =SUM(F20*G20) -> 100000 | I20: 200 | J20: =SUM(H20/I20) -> 500 | K20: 100 for setup 100 for user downloads
C21: Malls / parks | D21: 100000 | E21: 1 | F21: =SUM(D21*E21) -> 100000 | G21: 1 | H21: =SUM(F21*G21) -> 100000 | I21: 100 | J21: =SUM(H21/I21) -> 1000
C22: Society events | D22: 100000 | E22: 1 | F22: =SUM(D22*E22) -> 100000 | G22: 1 | H22: =SUM(F22*G22) -> 100000 | I22: 100 | J22: =SUM(H22/I22) -> 1000
B23: Corporate Onboarding | C23: Company MoU | D23: 500 | E23: 1 | F23: =SUM(D23*E23) -> 500 | G23: 30 | H23: =SUM(F23*G23) -> 15000 | I23: 500 | J23: =SUM(H23/I23) -> 30
C24: HR partnerships | D24: 100 | E24: 1 | F24: =SUM(D24*E24) -> 100 | G24: =SUM(G23*20) -> 600 | H24: =SUM(F24*G24) -> 60000 | I24: 100 | J24: =SUM(H24/I24) -> 600
C25: Internal employee offers | D25: 100 | E25: 1 | F25: =SUM(D25*E25) -> 100 | G25: =SUM(G24) -> 600 | H25: =SUM(F25*G25) -> 60000 | I25: 100 | J25: =SUM(H25/I25) -> 600
B26: Zero-CAC / Near-Zero CAC Channels | C26: Social share | D26: 100 | E26: 1 | F26: =SUM(D26*E26) -> 100 | G26: 10 | H26: =SUM(F26*G26) -> 1000 | I26: 1 | J26: =SUM(H26/I26) -> 1000
C27: organic content | D27: 100 | E27: 1 | F27: =SUM(D27*E27) -> 100 | G27: 10 | H27: =SUM(F27*G27) -> 1000 | I27: 1 | J27: =SUM(H27/I27) -> 1000
C28: word of mouth | D28: 100 | E28: 1 | F28: =SUM(D28*E28) -> 100 | G28: 10 | H28: =SUM(F28*G28) -> 1000 | I28: 1 | J28: =SUM(H28/I28) -> 1000
E29: 1 | F29: =SUM(D29*E29) -> 0
B30: PARTNERSHIPS | C30: Co-brand | D30: 20 | E30: 1 | F30: =SUM(D30*E30) -> 20 | G30: 1000 | H30: =SUM(F30*G30) -> 20000 | I30: 20 | J30: =SUM(H30/I30) -> 1000
D33: =SUM(D3:D30) -> 1714970 | F33: =SUM(F3:F30) -> 1714970 | H33: =SUM(H3:H30) -> 1768225 | I33: =SUM(H33/J33) -> 75.905231 | J33: =SUM(J3:J30) -> 23295.167
A34: NEW Customer Acquire
B35: Budget required | C35: CAC | D35: Total user
A36: Ideal Conditioin | B36: =SUM(H33) -> 1768225 | C36: =SUM(I33) -> 75.905231 | D36: =SUM(B36/C36) -> 23295.167
A37: CAC | B37: 100 | C37: =SUM(I33) -> 75.905231 | D37: =SUM(B37/C37) -> 1.3174323
A38: Starting Budget | B38: =SUM(Assumptions!B15) -> 300000 | C38: =SUM(I33) -> 75.905231 | D38: =SUM(B38/C38) -> 3952.2968
B45: Business Devloepment | C45: PAID ADS (META / GOOGLE) | D45: Meta app install ads
D46: Google UAC
C47: Events | D47: Merchant events
D48: Local events
C49: Refferal | D49: Merchant refers
D50: User Referrs
C51: Digital Marketing
...

Sheet Charts
E3: Revenue | F3: Net Profit
D5: Year 1 | E5: 0.782 | F5: 0.093
D6: Year 2 | E6: 2.4 | F6: 0.326
D7: Year 3 | E7: 24.9 | F7: 4.183
E24: Revenue | F24: Gross Profit | G24: Net Profit
D25: Year 1 | E25: =SUM('Income Statement'!B15) -> 1.0038019e+08 | F25: =SUM('Income Statement'!B34) -> 6087295.7 | G25: =SUM('Income Statement'!B36) -> 4261107
D26: Year 2 | E26: =SUM('Income Statement'!C15) -> 1533775039 | F26: =SUM('Income Statement'!C34) -> -7.2925453e+08 | G26: =SUM('Income Statement'!C36) -> -7.2925453e+08
D27: Year 3 | E27: =SUM('Income Statement'!D15) -> 5960777215 | F27: =SUM('Income Statement'!D34) -> 2036958070 | G27: =SUM('Income Statement'!D36) -> 1425870649
E30: =(E27-E25)/E25 -> 58.382005 | F30: =(F27-F25)/F25 -> 333.62446 | G30: =(G27-G25)/G25 -> 333.62446
